<robot
  name="rsc_car">
  <link
    name="base_link">
    <inertial>
      <origin
        xyz="0.060651 0.0059455 -0.014577"
        rpy="0 0 0" />
      <mass
        value="9.6392" />
      <inertia
        ixx="0.23781"
        ixy="-0.00095749"
        ixz="-0.0085705"
        iyy="0.19402"
        iyz="-0.00034651"
        izz="0.23821" />
    </inertial>
    <visual>
      <origin
        xyz="0 0 0"
        rpy="0 0 0" />
      <geometry>
        <mesh
          filename="package://rsc_car/meshes/base_link.STL" />
      </geometry>
      <material
        name="">
        <color
          rgba="0.79216 0.81961 0.93333 1" />
      </material>
    </visual>
    <collision>
      <origin
        xyz="0 0 0"
        rpy="0 0 0" />
      <geometry>
        <mesh
          filename="package://rsc_car/meshes/base_link.STL" />
      </geometry>
    </collision>
  </link>
  <link
    name="rwheel_link">
    <inertial>
      <origin
        xyz="0.001358 0.17299 -0.0017698"
        rpy="0 0 0" />
      <mass
        value="9.6392" />
      <inertia
        ixx="0.23223"
        ixy="-0.00077508"
        ixz="-0.00633"
        iyy="0.19402"
        iyz="-0.00066038"
        izz="0.24379" />
    </inertial>
    <visual>
      <origin
        xyz="0 0 0"
        rpy="0 0 0" />
      <geometry>
        <mesh
          filename="package://rsc_car/meshes/rwheel_link.STL" />
      </geometry>
      <material
        name="">
        <color
          rgba="0.79216 0.81961 0.93333 1" />
      </material>
    </visual>
    <collision>
      <origin
        xyz="0 0 0"
        rpy="0 0 0" />
      <geometry>
        <mesh
          filename="package://rsc_car/meshes/rwheel_link.STL" />
      </geometry>
    </collision>
  </link>
  <joint
    name="rwheel_joint"
    type="continuous">
    <origin
      xyz="0.06 -0.16704 -0.012443"
      rpy="5.2315E-18 0.35843 4.0076E-17" />
    <parent
      link="base_link" />
    <child
      link="rwheel_link" />
    <axis
      xyz="0 -1 0" />
  </joint>
  <link
    name="lwheel_link">
    <inertial>
      <origin
        xyz="-0.0022252 -0.17301 -0.00015742"
        rpy="0 0 0" />
      <mass
        value="9.6392" />
      <inertia
        ixx="0.23445"
        ixy="-0.00012371"
        ixz="0.007801"
        iyy="0.19402"
        iyz="0.0010107"
        izz="0.24156" />
    </inertial>
    <visual>
      <origin
        xyz="0 0 0"
        rpy="0 0 0" />
      <geometry>
        <mesh
          filename="package://rsc_car/meshes/lwheel_link.STL" />
      </geometry>
      <material
        name="">
        <color
          rgba="0.79216 0.81961 0.93333 1" />
      </material>
    </visual>
    <collision>
      <origin
        xyz="0 0 0"
        rpy="0 0 0" />
      <geometry>
        <mesh
          filename="package://rsc_car/meshes/lwheel_link.STL" />
      </geometry>
    </collision>
  </link>
  <joint
    name="lwheel_joint"
    type="continuous">
    <origin
      xyz="0.06 0.17896 -0.012443"
      rpy="-3.1416 -1.3454 3.1416" />
    <parent
      link="base_link" />
    <child
      link="lwheel_link" />
    <axis
      xyz="0 1 0" />
  </joint>
  <link
    name="hokuyo_link">
    <inertial>
      <origin
        xyz="2.6021E-18 -5.5511E-17 -0.01"
        rpy="0 0 0" />
      <mass
        value="0.392" />
      <inertia
        ixx="0.00036913"
        ixy="-4.8733E-20"
        ixz="-3.4465E-20"
        iyy="0.00036913"
        iyz="9.736E-20"
        izz="0.00032013" />
    </inertial>
    <visual>
      <origin
        xyz="0 0 0"
        rpy="0 0 0" />
      <geometry>
        <mesh
          filename="package://rsc_car/meshes/hokuyo_link.STL" />
      </geometry>
      <material
        name="">
        <color
          rgba="0.79216 0.81961 0.93333 1" />
      </material>
    </visual>
    <collision>
      <origin
        xyz="0 0 0"
        rpy="0 0 0" />
      <geometry>
        <mesh
          filename="package://rsc_car/meshes/hokuyo_link.STL" />
      </geometry>
    </collision>
  </link>
  <joint
    name="hokuyo_joint"
    type="fixed">
    <origin
      xyz="0.105 0.0059553 0.22856"
      rpy="-3.4915E-15 0 1.5708" />
    <parent
      link="base_link" />
    <child
      link="hokuyo_link" />
    <axis
      xyz="0 0 0" />
  </joint>
</robot>
